Workbook

Sheet 参数输入
A1: 【基础业务参数】
A2: 参数名称 | B2: 参数值 | C2: 单位 | D2: 备注
A3: 日均销量 | B3: 100 | C3: 件/天 | D3: 过去30天平均值
A4: 月销量 | B4: 3000 | C4: 件/月 | D4: 日均×30
A5: 产品单价 | B5: 50 | C5: 元/件 | D5: 产品成本价
A6: 毛利率 | B6: 30 | C6: % | D6: 售价=单价÷(1-毛利率)
A7: 资金成本率 | B7: 8 | C7: % | D7: 年化
A9: 【库存参数】
A10: 参数名称 | B10: 参数值 | C10: 单位 | D10: 备注
A11: 当前库存 | B11: 800 | C11: 件
A12: 在途库存 | B12: 300 | C12: 件
A13: 安全库存 | B13: 150 | C13: 件
A14: 补货周期 | B14: 7 | C14: 天
A15: 目标周转天数 | B15: 30 | C15: 天 | D15: 行业基准
A17: 【成本参数】
A18: 参数名称 | B18: 参数值 | C18: 单位 | D18: 备注
A19: 仓储费 | B19: 2 | C19: 元/件/月
A20: 持有成本率 | B20: 15 | C20: % | D20: 占产品单价比例
A21: 缺货成本率 | B21: 10 | C21: % | D21: 占产品单价比例
A22: 滞销定义天数 | B22: 90 | C22: 天 | D22: 超过算滞销
A24: 【分类标准】
A25: 参数名称 | B25: A类标准 | C25: B类标准 | D25: C类标准
A26: 销售额占比 | B26: 0.7 | C26: 0.2 | D26: 0.1
A27: 周转天数 | B27: <30天 | C27: 30-60天 | D27: >60天

Sheet 周转计算
A1: 【库存周转率计算】
A3: 计算项 | B3: 公式 | C3: 数值 | D3: 单位
A4: 月销量 | B4: 月销量（参数引用） | C4: =参数输入!B4 -> 3000 | D4: 件/月
A5: 月平均库存 | B5: (期初 + 期末) ÷ 2 | C5: =(参数输入!B11+参数输入!B11*0.8)/2 -> 720 | D5: 件
A6: 库存周转率(次) | B6: 月销量 ÷ 月平均库存 | C6: =C4/C5 -> 4.1666667 | D6: 次/月
A7: 库存周转天数 | B7: 30 ÷ 周转率 | C7: =30/C6 -> 7.2 | D7: 天
A8: 年库存周转率 | B8: 月周转率 × 12 | C8: =C6*12 -> 50 | D8: 次/年
A10: 【可卖天数计算】
A12: 计算项 | B12: 公式 | C12: 数值
A13: 当前库存 | B13: 当前库存（参数引用） | C13: =参数输入!B11 -> 800
A14: 在途库存 | B14: 在途库存（参数引用） | C14: =参数输入!B12 -> 300
A15: 有效库存 | B15: 当前库存 + 在途库存 | C15: =C13+C14 -> 1100 | D15: 件
A16: 日均销量 | B16: 日均销量（参数引用） | C16: =参数输入!B3 -> 100
A17: 可卖天数 | B17: 有效库存 ÷ 日均销量 | C17: =C15/C16 -> 11 | D17: 天
A19: 【库存健康度评估】
A21: 评估项 | B21: 当前值 | C21: 优秀 | D21: 良好 | E21: 警戒 | F21: 严重 | G21: 当前等级
A22: 周转天数 | B22: =C7 -> 7.2 | C22: <30 | D22: 30-45 | E22: 45-60 | F22: >60 | G22: =IF(C7<30,"🟢 优秀",IF(C7<45,"🟡 良好",IF(C7<60,"🟠 警戒","🔴 严重"))) -> 🟢 优秀
A23: 可卖天数 | B23: =C17 -> 11 | C23: >30 | D23: 20-30 | E23: 10-20天 | F23: <10 | G23: =IF(C17>30,"🟢 充足",IF(C17>20,"🟡 正常",IF(C17>10,"🟠 不足","🔴 断货风险"))) -> 🟠 不足
A24: 库存结构 | B24: =参数输入!B9 -> 0 | C24: - | D24: - | E24: - | F24: -
A26: 【ABC分类计算】
A28: SKU | B28: 月销量 | C28: 单价 | D28: 月销售额 | E28: 销售额占比 | F28: 累计占比 | G28: 分类
A29: SKU-A | B29: 500 | C29: 50 | D29: =B29*C29 -> 25000 | E29: =D29/SUM($D$29:$D$38) -> 0.38610039 | F29: =SUM($E$29:E29) -> 0.38610039 | G29: =IF(F29<=0.7,"A",IF(F29<=0.9,"B","C")) -> A
A30: SKU-B | B30: 300 | C30: 50 | D30: =B30*C30 -> 15000 | E30: =D30/SUM($D$29:$D$38) -> 0.23166023 | F30: =SUM($E$29:E30) -> 0.61776062 | G30: =IF(F30<=0.7,"A",IF(F30<=0.9,"B","C")) -> A
A31: SKU-C | B31: 200 | C31: 50 | D31: =B31*C31 -> 10000 | E31: =D31/SUM($D$29:$D$38) -> 0.15444015 | F31: =SUM($E$29:E31) -> 0.77220077 | G31: =IF(F31<=0.7,"A",IF(F31<=0.9,"B","C")) -> B
A32: SKU-D | B32: 100 | C32: 50 | D32: =B32*C32 -> 5000 | E32: =D32/SUM($D$29:$D$38) -> 0.077220077 | F32: =SUM($E$29:E32) -> 0.84942085 | G32: =IF(F32<=0.7,"A",IF(F32<=0.9,"B","C")) -> B
A33: SKU-E | B33: 80 | C33: 50 | D33: =B33*C33 -> 4000 | E33: =D33/SUM($D$29:$D$38) -> 0.061776062 | F33: =SUM($E$29:E33) -> 0.91119691 | G33: =IF(F33<=0.7,"A",IF(F33<=0.9,"B","C")) -> C
A34: SKU-F | B34: 50 | C34: 50 | D34: =B34*C34 -> 2500 | E34: =D34/SUM($D$29:$D$38) -> 0.038610039 | F34: =SUM($E$29:E34) -> 0.94980695 | G34: =IF(F34<=0.7,"A",IF(F34<=0.9,"B","C")) -> C
A35: SKU-G | B35: 30 | C35: 50 | D35: =B35*C35 -> 1500 | E35: =D35/SUM($D$29:$D$38) -> 0.023166023 | F35: =SUM($E$29:E35) -> 0.97297297 | G35: =IF(F35<=0.7,"A",IF(F35<=0.9,"B","C")) -> C
A36: SKU-H | B36: 20 | C36: 50 | D36: =B36*C36 -> 1000 | E36: =D36/SUM($D$29:$D$38) -> 0.015444015 | F36: =SUM($E$29:E36) -> 0.98841699 | G36: =IF(F36<=0.7,"A",IF(F36<=0.9,"B","C")) -> C
A37: SKU-I | B37: 10 | C37: 50 | D37: =B37*C37 -> 500 | E37: =D37/SUM($D$29:$D$38) -> 0.0077220077 | F37: =SUM($E$29:E37) -> 0.996139 | G37: =IF(F37<=0.7,"A",IF(F37<=0.9,"B","C")) -> C
A38: SKU-J | B38: 5 | C38: 50 | D38: =B38*C38 -> 250 | E38: =D38/SUM($D$29:$D$38) -> 0.0038610039 | F38: =SUM($E$29:E38) -> 1 | G38: =IF(F38<=0.7,"A",IF(F38<=0.9,"B","C")) -> C
A39: 合计 | B39: =SUM(B29:B38) -> 1295 | D39: =SUM(D29:D38) -> 64750
A41: 【ABC分类策略】
A43: 分类 | B43: 数量占比 | C43: 销售额占比 | D43: 管理策略 | E43: 库存水平
A44: A类 | B44: =COUNTIF($G$29:$G$38,"A")/10 -> 0.2 | C44: =SUMIF($G$29:$G$38,"A",$D$29:$D$38)/SUM($D$29:$D$38) -> 0.61776062 | D44: 重点管理、高频盘点 | E44: 低库存、快周转
A45: B类 | B45: =COUNTIF($G$29:$G$38,"B")/10 -> 0.2 | C45: =SUMIF($G$29:$G$38,"B",$D$29:$D$38)/SUM($D$29:$D$38) -> 0.23166023 | D45: 常规管理 | E45: 中等库存
A46: C类 | B46: =COUNTIF($G$29:$G$38,"C")/10 -> 0.6 | C46: =SUMIF($G$29:$G$38,"C",$D$29:$D$38)/SUM($D$29:$D$38) -> 0.15057915 | D46: 简单管理、批量订货 | E46: 高库存、低周转
A48: 【库龄分析】
A50: 库龄区间 | B50: 库存数量 | C50: 占比 | D50: 处理建议
A51: 0-30天 | B51: 500 | C51: =B51/SUM($B$51:$B$54) -> 0.58823529 | D51: 正常销售
...

Sheet 策略对比
A1: 【库存周转策略对比】
A3: 策略名称 | B3: 目标周转天数 | C3: 安全库存水平 | D3: 补货频率 | E3: 适用场景 | F3: 优点 | G3: 缺点
A4: 高周转策略 | B4: 15天 | C4: 低 | D4: 高频次 | E4: 高毛利、快消品 | F4: 资金占用少 | G4: 断货风险高
A5: 平衡策略 | B5: 30天 | C5: 中 | D5: 中频次 | E5: 常规产品 | F5: 风险可控 | G5: 资金占用中等
A6: 低周转策略 | B6: 60天 | C6: 高 | D6: 低频次 | E6: 低毛利、大件 | F6: 供应稳定 | G6: 资金占用高
A8: 【不同品类策略对比】
A10: 品类 | B10: 推荐策略 | C10: 目标周转天数 | D10: 安全库存 | E10: 管理重点
A11: A类(高价值) | B11: 高周转策略 | C11: 15天 | D11: =参数输入!B11*0.5 -> 400 | E11: 精准预测、高频补货
A12: B类(常规) | B12: 平衡策略 | C12: 30天 | D12: =参数输入!B11 -> 800 | E12: 定期复盘
A13: C类(低价值) | B13: 低周转策略 | C13: 60天 | D13: =参数输入!B11*2 -> 1600 | E13: 批量采购、减少精力
A15: 【库存优化方案对比】
A17: 方案 | B17: 措施 | C17: 预期效果 | D17: 实施难度 | E17: ROI
A18: 方案1 | B18: ABC分类管理 | C18: 周转提升20% | D18: 低 | E18: 高
A19: 方案2 | B19: 滞销品清理 | C19: 释放资金15% | D19: 中 | E19: 高
A20: 方案3 | B20: 安全库存优化 | C20: 降低库存10% | D20: 中 | E20: 中
A21: 方案4 | B21: 补货频率调整 | C21: 周转提升15% | D21: 低 | E21: 中
A22: 方案5 | B22: 供应商协同 | C22: 周转提升25% | D22: 高 | E22: 高
A24: 【当前库存问题诊断】
A26: 问题类型 | B26: 判断标准 | C26: 当前值 | D26: 是否有问题 | E26: 建议
A27: 库存过高 | B27: 可卖天数>45天 | C27: =周转计算!C17 -> 11 | D27: =IF(C27>45,"是","否") -> 否 | E27: 清理滞销、停止补货
A28: 库存不足 | B28: 可卖天数<10天 | C28: =周转计算!C17 -> 11 | D28: =IF(C28<10,"是","否") -> 否 | E28: 紧急补货
A29: 周转过慢 | B29: 周转天数>60天 | C29: =周转计算!C7 -> 7.2 | D29: =IF(C29>60,"是","否") -> 否 | E29: 分析原因、促销
A30: 滞销占比 | B30: 90天以上库存>20% | C30: =周转计算!B54/SUM(周转计算!B51:B54) -> 0.058823529 | D30: =IF(C30>0.2,"是","否") -> 否 | E30: 清仓处理

Sheet 敏感度分析
A1: 【销量波动对周转的影响】
A3: 销量变化 | B3: 月销量 | C3: 平均库存 | D3: 周转率(次) | E3: 周转天数 | F3: 影响说明
A4: -0.5 | B4: =参数输入!$B$4*0.5 -> 1500 | C4: =参数输入!$B$11 -> 800 | D4: =B4/C4 -> 1.875 | E4: =30/D4 -> 16 | F4: 销量下降，周转变慢
A5: -0.3 | B5: =参数输入!$B$4*0.7 -> 2100 | C5: =参数输入!$B$11 -> 800 | D5: =B5/C5 -> 2.625 | E5: =30/D5 -> 11.428571 | F5: 销量下降，周转变慢
A6: 0 | B6: =参数输入!$B$4*1 -> 3000 | C6: =参数输入!$B$11 -> 800 | D6: =B6/C6 -> 3.75 | E6: =30/D6 -> 8 | F6: 基准
A7: 0.3 | B7: =参数输入!$B$4*1.3 -> 3900 | C7: =参数输入!$B$11 -> 800 | D7: =B7/C7 -> 4.875 | E7: =30/D7 -> 6.1538462 | F7: 销量上升，周转加快
A8: 0.5 | B8: =参数输入!$B$4*1.5 -> 4500 | C8: =参数输入!$B$11 -> 800 | D8: =B8/C8 -> 5.625 | E8: =30/D8 -> 5.3333333 | F8: 销量上升，周转加快
A10: 【库存水平对周转的影响】
A12: 库存变化 | B12: 库存数量 | C12: 周转率(次) | D12: 周转天数 | E12: 资金占用(元)
A13: -0.5 | B13: =参数输入!$B$11*0.5 -> 400 | C13: =参数输入!$B$4/B13 -> 7.5 | D13: =30/C13 -> 4 | E13: =B13*参数输入!$B$5 -> 20000
A14: -0.3 | B14: =参数输入!$B$11*0.7 -> 560 | C14: =参数输入!$B$4/B14 -> 5.3571429 | D14: =30/C14 -> 5.6 | E14: =B14*参数输入!$B$5 -> 28000
A15: 0 | B15: =参数输入!$B$11*1 -> 800 | C15: =参数输入!$B$4/B15 -> 3.75 | D15: =30/C15 -> 8 | E15: =B15*参数输入!$B$5 -> 40000
A16: 0.3 | B16: =参数输入!$B$11*1.3 -> 1040 | C16: =参数输入!$B$4/B16 -> 2.8846154 | D16: =30/C16 -> 10.4 | E16: =B16*参数输入!$B$5 -> 52000
A17: 0.5 | B17: =参数输入!$B$11*1.5 -> 1200 | C17: =参数输入!$B$4/B17 -> 2.5 | D17: =30/C17 -> 12 | E17: =B17*参数输入!$B$5 -> 60000
A19: 【周转天数优化目标分析】
A21: 目标周转天数 | B21: 所需月销量 | C21: 所需平均库存 | D21: 库存调整幅度 | E21: 建议
A22: 20天 | B22: =参数输入!$B$4 -> 3000 | C22: =参数输入!$B$4*20/30 -> 2000 | D22: =C22-参数输入!$B$11 -> 1200 | E22: 增加销量或降库存
A23: 25天 | B23: =参数输入!$B$4 -> 3000 | C23: =参数输入!$B$4*25/30 -> 2500 | D23: =C23-参数输入!$B$11 -> 1700 | E23: 适度优化
A24: 30天 | B24: =参数输入!$B$4 -> 3000 | C24: =参数输入!$B$4*30/30 -> 3000 | D24: =C24-参数输入!$B$11 -> 2200 | E24: 当前基准
A25: 35天 | B25: =参数输入!$B$4 -> 3000 | C25: =参数输入!$B$4*35/30 -> 3500 | D25: =C25-参数输入!$B$11 -> 2700 | E25: 可接受范围
A26: 40天 | B26: =参数输入!$B$4 -> 3000 | C26: =参数输入!$B$4*40/30 -> 4000 | D26: =C26-参数输入!$B$11 -> 3200 | E26: 需要优化
A28: 【敏感度结论】
A30: 敏感因素 | B30: 影响程度 | C30: 控制建议
A31: 销量波动 | B31: 高 | C31: 每周更新预测，动态调整库存
A32: 补货周期 | B32: 中 | C32: 优化供应链，缩短周期
A33: 采购批量 | B33: 中 | C33: 用EOQ模型计算最优批量
A34: 产品生命周期 | B34: 高 | C34: 新品少备货，衰退期清库存
A35: 季节性 | B35: 高 | C35: 提前2个月调整安全库存

Sheet 使用说明
A1: 【库存周转策略模型使用说明】
A3: 一、模型核心逻辑
A5: 本模型基于库存周转率、可卖天数、ABC分类等指标，
A6: 评估库存健康度，提供不同品类的库存管理策略，
A7: 帮助优化库存水平，提高资金使用效率。
A9: 二、核心指标定义
A11: 1. 库存周转率 = 月销量 ÷ 月平均库存
A12: - 衡量库存流动速度
A13: - 越高越好，说明周转快
A15: 2. 库存周转天数 = 30 ÷ 库存周转率
A16: - 从入库到卖出的平均天数
A17: - 越低越好
... A138: 📅 每年：重新评估策略
