Workbook

Sheet 参数输入
A1: 【基础业务参数】
A2: 参数名称 | B2: 参数值 | C2: 单位 | D2: 备注
A3: 日均销量 | B3: 100 | C3: 件/天
A4: 产品单价 | B4: 50 | C4: 元/件
A5: 客户容忍时效 | B5: 7 | C5: 天 | D5: 超过可能产生客诉
A6: 标准预警阈值 | B6: 48 | C6: 小时 | D6: 超过算异常
A7: 严重预警阈值 | B7: 96 | C7: 小时 | D7: 超过算严重异常
A9: 【头程时效参数】
A10: 路线 | B10: 运输方式 | C10: 标准时效(小时) | D10: 标准时效(天) | E10: 运费(元/kg) | F10: 单件重量(kg) | G10: 固定成本(元/票)
A11: 美西 | B11: 海运 | C11: 360 | D11: 15 | E11: 12 | F11: 1.2 | G11: 800
A12: 美西 | B12: 空运 | C12: 48 | D12: 2 | E12: 32 | F12: 1.2 | G12: 300
A13: 美西 | B13: 铁运 | C13: 480 | D13: 20 | E13: 18 | F13: 1.2 | G13: 500
A14: 美东 | B14: 海运 | C14: 480 | D14: 20 | E14: 14 | F14: 1.2 | G14: 800
A15: 美东 | B15: 空运 | C15: 56 | D15: 2.3 | E15: 35 | F15: 1.2 | G15: 300
A16: 美东 | B16: 铁运 | C16: 600 | D16: 25 | E16: 20 | F16: 1.2 | G16: 500
A17: 欧洲 | B17: 海运 | C17: 720 | D17: 30 | E17: 16 | F17: 1.2 | G17: 1000
A18: 欧洲 | B18: 空运 | C18: 60 | D18: 2.5 | E18: 38 | F18: 1.2 | G18: 400
A19: 欧洲 | B19: 铁运 | C19: 360 | D19: 15 | E19: 22 | F19: 1.2 | G19: 600
A20: 东南亚 | B20: 海运 | C20: 120 | D20: 5 | E20: 8 | F20: 1.2 | G20: 400
A21: 东南亚 | B21: 空运 | C21: 24 | D21: 1 | E21: 18 | F21: 1.2 | G21: 200
A22: 日韩 | B22: 海运 | C22: 96 | D22: 4 | E22: 6 | F22: 1.2 | G22: 300
A23: 日韩 | B23: 空运 | C23: 12 | D23: 0.5 | E23: 15 | F23: 1.2 | G23: 150
A25: 【尾程时效参数】
A26: 路线 | B26: 服务商 | C26: 标准时效(天) | D26: 首重(kg) | E26: 首重价格(元) | F26: 续重单价(元/kg)
A27: 美西 | B27: USPS | C27: 3 | D27: 0.5 | E27: 35 | F27: 8
A28: 美西 | B28: FedEx | C28: 2 | D28: 1 | E28: 42 | F28: 6
A29: 美东 | B29: USPS | C29: 3 | D29: 0.5 | E29: 38 | F29: 9
A30: 美东 | B30: FedEx | C30: 2 | D30: 1 | E30: 45 | F30: 7
A31: 欧洲 | B31: DPD | C31: 3 | D31: 0.5 | E31: 40 | F31: 10
A32: 欧洲 | B32: UPS | C32: 2 | D32: 1 | E32: 50 | F32: 9
A33: 东南亚 | B33: J&T | C33: 2 | D33: 0.5 | E33: 25 | F33: 5
A34: 东南亚 | B34: DHL | C34: 1 | D34: 1 | E34: 35 | F34: 8
A35: 日韩 | B35: 佐川 | C35: 2 | D35: 0.5 | E35: 20 | F35: 4
A36: 日韩 | B36: Yamato | C36: 2 | D36: 1 | E36: 28 | F36: 6
A38: 【时效权重参数】
A39: 权重项 | B39: 权重 | C39: 说明
A40: 时效权重 | B40: 0.6 | C40: 时效优先型产品
A41: 成本权重 | B41: 0.4 | C41: 时效优先型产品
A43: 【约束参数】
A44: 约束项 | B44: 参数值 | C44: 单位
...

Sheet 时效计算
A1: 【头程时效分析】
A3: 路线 | B3: 运输方式 | C3: 标准时效(天) | D3: 单件运费(元) | E3: 单件头程成本(元) | F3: 时效等级
A4: 美西 | B4: 海运 | C4: =参数输入!D11 -> 15 | D4: =参数输入!E11*参数输入!F11 -> 14.4 | E4: =D4+参数输入!G11/1000 -> 15.2 | F4: =IF(C4<=2,"🟢 快速",IF(C4<=5,"🟡 正常","🔴 慢速")) -> 🔴 慢速
A5: 美西 | B5: 空运 | C5: =参数输入!D12 -> 2 | D5: =参数输入!E12*参数输入!F12 -> 38.4 | E5: =D5+参数输入!G12/1000 -> 38.7 | F5: =IF(C5<=2,"🟢 快速",IF(C5<=5,"🟡 正常","🔴 慢速")) -> 🟢 快速
A6: 美西 | B6: 铁运 | C6: =参数输入!D13 -> 20 | D6: =参数输入!E13*参数输入!F13 -> 21.6 | E6: =D6+参数输入!G13/1000 -> 22.1 | F6: =IF(C6<=2,"🟢 快速",IF(C6<=5,"🟡 正常","🔴 慢速")) -> 🔴 慢速
A7: 美东 | B7: 海运 | C7: =参数输入!D14 -> 20 | D7: =参数输入!E14*参数输入!F14 -> 16.8 | E7: =D7+参数输入!G14/1000 -> 17.6 | F7: =IF(C7<=2,"🟢 快速",IF(C7<=5,"🟡 正常","🔴 慢速")) -> 🔴 慢速
A8: 美东 | B8: 空运 | C8: =参数输入!D15 -> 2.3 | D8: =参数输入!E15*参数输入!F15 -> 42 | E8: =D8+参数输入!G15/1000 -> 42.3 | F8: =IF(C8<=2,"🟢 快速",IF(C8<=5,"🟡 正常","🔴 慢速")) -> 🟡 正常
A9: 美东 | B9: 铁运 | C9: =参数输入!D16 -> 25 | D9: =参数输入!E16*参数输入!F16 -> 24 | E9: =D9+参数输入!G16/1000 -> 24.5 | F9: =IF(C9<=2,"🟢 快速",IF(C9<=5,"🟡 正常","🔴 慢速")) -> 🔴 慢速
A10: 欧洲 | B10: 海运 | C10: =参数输入!D17 -> 30 | D10: =参数输入!E17*参数输入!F17 -> 19.2 | E10: =D10+参数输入!G17/1000 -> 20.2 | F10: =IF(C10<=2,"🟢 快速",IF(C10<=5,"🟡 正常","🔴 慢速")) -> 🔴 慢速
A11: 欧洲 | B11: 空运 | C11: =参数输入!D18 -> 2.5 | D11: =参数输入!E18*参数输入!F18 -> 45.6 | E11: =D11+参数输入!G18/1000 -> 46 | F11: =IF(C11<=2,"🟢 快速",IF(C11<=5,"🟡 正常","🔴 慢速")) -> 🟡 正常
A12: 欧洲 | B12: 铁运 | C12: =参数输入!D19 -> 15 | D12: =参数输入!E19*参数输入!F19 -> 26.4 | E12: =D12+参数输入!G19/1000 -> 27 | F12: =IF(C12<=2,"🟢 快速",IF(C12<=5,"🟡 正常","🔴 慢速")) -> 🔴 慢速
A13: 东南亚 | B13: 海运 | C13: =参数输入!D20 -> 5 | D13: =参数输入!E20*参数输入!F20 -> 9.6 | E13: =D13+参数输入!G20/1000 -> 10 | F13: =IF(C13<=2,"🟢 快速",IF(C13<=5,"🟡 正常","🔴 慢速")) -> 🟡 正常
A14: 东南亚 | B14: 空运 | C14: =参数输入!D21 -> 1 | D14: =参数输入!E21*参数输入!F21 -> 21.6 | E14: =D14+参数输入!G21/1000 -> 21.8 | F14: =IF(C14<=2,"🟢 快速",IF(C14<=5,"🟡 正常","🔴 慢速")) -> 🟢 快速
A15: 日韩 | B15: 海运 | C15: =参数输入!D22 -> 4 | D15: =参数输入!E22*参数输入!F22 -> 7.2 | E15: =D15+参数输入!G22/1000 -> 7.5 | F15: =IF(C15<=2,"🟢 快速",IF(C15<=5,"🟡 正常","🔴 慢速")) -> 🟡 正常
A16: 日韩 | B16: 空运 | C16: =参数输入!D23 -> 0.5 | D16: =参数输入!E23*参数输入!F23 -> 18 | E16: =D16+参数输入!G23/1000 -> 18.15 | F16: =IF(C16<=2,"🟢 快速",IF(C16<=5,"🟡 正常","🔴 慢速")) -> 🟢 快速
A18: 【全链路时效计算】
A20: 路线 | B20: 运输方式 | C20: 头程时效(天) | D20: 尾程时效(天) | E20: 全链路时效(天) | F20: 时效等级 | G20: 是否超客户容忍
A21: 美西 | B21: 海运 | C21: =参数输入!D11 -> 15 | D21: =参数输入!D27 -> 0.5 | E21: =C21+D21 -> 15.5 | F21: =IF(E21<=3,"🟢 优秀",IF(E21<=5,"🟡 正常",IF(E21<=10,"🟠 较慢","🔴 超时"))) -> 🔴 超时 | G21: =IF(E21>参数输入!$B$5,"是","否") -> 是
A22: 美西 | B22: 空运 | C22: =参数输入!D12 -> 2 | D22: =参数输入!D27 -> 0.5 | E22: =C22+D22 -> 2.5 | F22: =IF(E22<=3,"🟢 优秀",IF(E22<=5,"🟡 正常",IF(E22<=10,"🟠 较慢","🔴 超时"))) -> 🟢 优秀 | G22: =IF(E22>参数输入!$B$5,"是","否") -> 否
A23: 美西 | B23: 铁运 | C23: =参数输入!D13 -> 20 | D23: =参数输入!D27 -> 0.5 | E23: =C23+D23 -> 20.5 | F23: =IF(E23<=3,"🟢 优秀",IF(E23<=5,"🟡 正常",IF(E23<=10,"🟠 较慢","🔴 超时"))) -> 🔴 超时 | G23: =IF(E23>参数输入!$B$5,"是","否") -> 是
A24: 美东 | B24: 海运 | C24: =参数输入!D14 -> 20 | D24: =参数输入!D29 -> 0.5 | E24: =C24+D24 -> 20.5 | F24: =IF(E24<=3,"🟢 优秀",IF(E24<=5,"🟡 正常",IF(E24<=10,"🟠 较慢","🔴 超时"))) -> 🔴 超时 | G24: =IF(E24>参数输入!$B$5,"是","否") -> 是
A25: 美东 | B25: 空运 | C25: =参数输入!D15 -> 2.3 | D25: =参数输入!D29 -> 0.5 | E25: =C25+D25 -> 2.8 | F25: =IF(E25<=3,"🟢 优秀",IF(E25<=5,"🟡 正常",IF(E25<=10,"🟠 较慢","🔴 超时"))) -> 🟢 优秀 | G25: =IF(E25>参数输入!$B$5,"是","否") -> 否
A26: 美东 | B26: 铁运 | C26: =参数输入!D16 -> 25 | D26: =参数输入!D29 -> 0.5 | E26: =C26+D26 -> 25.5 | F26: =IF(E26<=3,"🟢 优秀",IF(E26<=5,"🟡 正常",IF(E26<=10,"🟠 较慢","🔴 超时"))) -> 🔴 超时 | G26: =IF(E26>参数输入!$B$5,"是","否") -> 是
A27: 欧洲 | B27: 海运 | C27: =参数输入!D17 -> 30 | D27: =参数输入!D31 -> 0.5 | E27: =C27+D27 -> 30.5 | F27: =IF(E27<=3,"🟢 优秀",IF(E27<=5,"🟡 正常",IF(E27<=10,"🟠 较慢","🔴 超时"))) -> 🔴 超时 | G27: =IF(E27>参数输入!$B$5,"是","否") -> 是
A28: 欧洲 | B28: 空运 | C28: =参数输入!D18 -> 2.5 | D28: =参数输入!D31 -> 0.5 | E28: =C28+D28 -> 3 | F28: =IF(E28<=3,"🟢 优秀",IF(E28<=5,"🟡 正常",IF(E28<=10,"🟠 较慢","🔴 超时"))) -> 🟢 优秀 | G28: =IF(E28>参数输入!$B$5,"是","否") -> 否
A29: 欧洲 | B29: 铁运 | C29: =参数输入!D19 -> 15 | D29: =参数输入!D31 -> 0.5 | E29: =C29+D29 -> 15.5 | F29: =IF(E29<=3,"🟢 优秀",IF(E29<=5,"🟡 正常",IF(E29<=10,"🟠 较慢","🔴 超时"))) -> 🔴 超时 | G29: =IF(E29>参数输入!$B$5,"是","否") -> 是
A30: 东南亚 | B30: 海运 | C30: =参数输入!D20 -> 5 | D30: =参数输入!D33 -> 0.5 | E30: =C30+D30 -> 5.5 | F30: =IF(E30<=3,"🟢 优秀",IF(E30<=5,"🟡 正常",IF(E30<=10,"🟠 较慢","🔴 超时"))) -> 🟠 较慢 | G30: =IF(E30>参数输入!$B$5,"是","否") -> 否
A31: 东南亚 | B31: 空运 | C31: =参数输入!D21 -> 1 | D31: =参数输入!D33 -> 0.5 | E31: =C31+D31 -> 1.5 | F31: =IF(E31<=3,"🟢 优秀",IF(E31<=5,"🟡 正常",IF(E31<=10,"🟠 较慢","🔴 超时"))) -> 🟢 优秀 | G31: =IF(E31>参数输入!$B$5,"是","否") -> 否
A32: 日韩 | B32: 海运 | C32: =参数输入!D22 -> 4 | D32: =参数输入!D35 -> 0.5 | E32: =C32+D32 -> 4.5 | F32: =IF(E32<=3,"🟢 优秀",IF(E32<=5,"🟡 正常",IF(E32<=10,"🟠 较慢","🔴 超时"))) -> 🟡 正常 | G32: =IF(E32>参数输入!$B$5,"是","否") -> 否
A33: 日韩 | B33: 空运 | C33: =参数输入!D23 -> 0.5 | D33: =参数输入!D35 -> 0.5 | E33: =C33+D33 -> 1 | F33: =IF(E33<=3,"🟢 优秀",IF(E33<=5,"🟡 正常",IF(E33<=10,"🟠 较慢","🔴 超时"))) -> 🟢 优秀 | G33: =IF(E33>参数输入!$B$5,"是","否") -> 否
A35: 【时效汇总统计】
A37: 统计项 | B37: 数值
A38: 总路线数 | B38: =COUNTA(A21:A33) -> 13
A39: 时效优秀(≤3天) | B39: =COUNTIF(F21:F33,"🟢 优秀") -> 5
A40: 时效正常(≤5天) | B40: =COUNTIF(F21:F33,"🟡 正常") -> 1
A41: 时效超时(>5天) | B41: =COUNTIF(F21:F33,"🟠 较慢")+COUNTIF(F21:F33,"🔴 超时") -> 7
A42: 超客户容忍 | B42: =COUNTIF(G21:G33,"是") -> 6
A43: 平均全链路时效(天) | B43: =AVERAGE(E21:E33) -> 11.446154
A44: 最快渠道 | B44: =INDEX(A21:A33,MATCH(MIN(E21:E33),E21:E33,0))&"+"&INDEX(B21:B33,MATCH(MIN(E21:E33),E21:E33,0)) -> 日韩+空运
A45: 最慢渠道 | B45: =INDEX(A21:A33,MATCH(MAX(E21:E33),E21:E33,0))&"+"&INDEX(B21:B33,MATCH(MAX(E21:E33),E21:E33,0)) -> 欧洲+海运
...

Sheet 策略对比
A1: 【物流时效策略对比】
A3: 策略类型 | B3: 适用场景 | C3: 推荐路线组合 | D3: 平均时效(天) | E3: 平均成本(元/件) | F3: 时效等级 | G3: 优缺点
A4: 时效优先 | B4: 高毛利、急用、新品测款 | C4: 空运 + 快速尾程 | D4: =时效计算!E22 -> 2.5 | E4: =时效计算!E22/2+5 -> 6.25 | F4: =时效计算!F22 -> 🟢 优秀 | G4: 优点：快、资金周转快；缺点：贵
A5: 平衡策略 | B5: 常规产品、性价比 | C5: 铁运 + 标准尾程 | D5: =时效计算!E23 -> 20.5 | E5: =时效计算!E23/2+5 -> 15.25 | F5: =时效计算!F23 -> 🔴 超时 | G5: 优点：性价比高；缺点：速度中等
A6: 成本优先 | B6: 低毛利、不着急、大货 | C6: 海运 + 经济尾程 | D6: =时效计算!E21 -> 15.5 | E6: =时效计算!E21/2+5 -> 12.75 | F6: =时效计算!F21 -> 🔴 超时 | G6: 优点：便宜；缺点：慢、占资金
A7: 美东时效优先 | B7: 美东高毛利产品 | C7: 美东空运 + 美东快速 | D7: =时效计算!E25 -> 2.8 | E7: =时效计算!E25/2+5 -> 6.4 | F7: =时效计算!F25 -> 🟢 优秀 | G7: 美东空运时效56小时
A8: 美东平衡策略 | B8: 美东常规产品 | C8: 美东铁运 + 美东标准 | D8: =时效计算!E26 -> 25.5 | E8: =时效计算!E26/2+5 -> 17.75 | F8: =时效计算!F26 -> 🔴 超时 | G8: 美东铁运600小时
A9: 美东成本优先 | B9: 美东低价产品 | C9: 美东海运 + 美东经济 | D9: =时效计算!E24 -> 20.5 | E9: =时效计算!E24/2+5 -> 15.25 | F9: =时效计算!F24 -> 🔴 超时 | G9: 美东海运20天
A10: 欧洲时效优先 | B10: 欧洲高毛利 | C10: 欧洲空运 + 欧洲快速 | D10: =时效计算!E28 -> 3 | E10: =时效计算!E28/2+5 -> 6.5 | F10: =时效计算!F28 -> 🟢 优秀 | G10: 欧洲空运60小时
A11: 欧洲平衡策略 | B11: 欧洲常规 | C11: 欧洲铁运 + 欧洲标准 | D11: =时效计算!E29 -> 15.5 | E11: =时效计算!E29/2+5 -> 12.75 | F11: =时效计算!F29 -> 🔴 超时 | G11: 欧洲铁运15天
A12: 欧洲成本优先 | B12: 欧洲低价 | C12: 欧洲海运 + 欧洲经济 | D12: =时效计算!E27 -> 30.5 | E12: =时效计算!E27/2+5 -> 20.25 | F12: =时效计算!F27 -> 🔴 超时 | G12: 欧洲海运30天
A13: 东南亚时效优先 | B13: 东南亚急用 | C13: 东南亚空运 + DHL | D13: =时效计算!E31 -> 1.5 | E13: =时效计算!E31/2+5 -> 5.75 | F13: =时效计算!F31 -> 🟢 优秀 | G13: 东南亚空运24小时
A14: 东南亚成本优先 | B14: 东南亚大货 | C14: 东南亚海运 + J&T | D14: =时效计算!E30 -> 5.5 | E14: =时效计算!E30/2+5 -> 7.75 | F14: =时效计算!F30 -> 🟠 较慢 | G14: 东南亚海运5天
A15: 日韩时效优先 | B15: 日韩急用 | C15: 日韩空运 + 佐川 | D15: =时效计算!E33 -> 1 | E15: =时效计算!E33/2+5 -> 5.5 | F15: =时效计算!F33 -> 🟢 优秀 | G15: 日韩空运12小时
A16: 日韩成本优先 | B16: 日韩大货 | C16: 日韩海运 + 佐川 | D16: =时效计算!E32 -> 4.5 | E16: =时效计算!E32/2+5 -> 7.25 | F16: =时效计算!F32 -> 🟡 正常 | G16: 日韩海运4天
A18: 【时效成本对比分析】
A20: 策略 | B20: 时效(天) | C20: 成本(元/件) | D20: 时效比成本 | E20: 推荐指数
A21: 时效优先 | B21: =时效计算!E22 -> 2.5 | C21: =时效计算!E22/2+5 -> 6.25 | D21: =B21/C21 -> 0.4 | E21: =IF(B21<5,"⭐⭐⭐⭐⭐","⭐⭐⭐") -> ⭐⭐⭐⭐⭐
A22: 平衡策略 | B22: =时效计算!E23 -> 20.5 | C22: =时效计算!E23/2+5 -> 15.25 | D22: =B22/C22 -> 1.3442623 | E22: =IF(AND(B22<10,C22<30),"⭐⭐⭐⭐⭐","⭐⭐⭐") -> ⭐⭐⭐
A23: 成本优先 | B23: =时效计算!E21 -> 15.5 | C23: =时效计算!E21/2+5 -> 12.75 | D23: =B23/C23 -> 1.2156863 | E23: =IF(C23<15,"⭐⭐⭐⭐⭐","⭐⭐") -> ⭐⭐⭐⭐⭐
A25: 【路线效率排名】
A27: 排名 | B27: 路线 | C27: 运输方式 | D27: 全链路时效(天) | E27: 综合评分
A28: 1 | B28: =INDEX(时效计算!A21:A33,MATCH(MIN(时效计算!E21:E33),时效计算!E21:E33,0)) -> 日韩 | C28: =INDEX(时效计算!B21:B33,MATCH(MIN(时效计算!E21:E33),时效计算!E21:E33,0)) -> 空运 | D28: =MIN(时效计算!E21:E33) -> 1 | E28: =MAX(时效计算!G50:G55) -> 6.154

Sheet 敏感度分析
A1: 【时效敏感度分析】
A3: 时效变化因素 | B3: 变化幅度 | C3: 时效影响(天) | D3: 成本影响(元) | E3: 建议
A4: 头程延误 | B4: 0.2 | C4: =参数输入!D3*0.2 -> 0 | D4: 0 | E4: 提前备货、增加安全库存
A5: 头程延误 | B5: 0.5 | C5: =参数输入!D3*0.5 -> 0 | D5: 0 | E5: 切换备用渠道
A6: 清关延误 | B6: +5天 | C6: 5 | D6: =参数输入!B4*参数输入!B5/365*5 -> 4.7945205 | E6: 选择包税渠道
A7: 尾程延误 | B7: +2天 | C7: 2 | D7: 0 | E7: 更换尾程服务商
A9: 【销量对时效策略的影响】
A11: 日均销量 | B11: 推荐策略 | C11: 理由
A12: <50件 | B12: 空运 | C12: 销量小，可承受较高运费
A13: 50-200件 | B13: 铁运 | C13: 性价比最高
A14: >200件 | B14: 海运 | C14: 量大，分摊固定成本
A16: 【产品单价对时效策略的影响】
A18: 产品单价(元) | B18: 推荐策略 | C18: 时效容忍度
A19: <20 | B19: 海运 | C19: 客户价格敏感，可接受慢时效
A20: 20-100 | B20: 铁运 | C20: 平衡策略
A21: >100 | B21: 空运 | C21: 高价值，客户期待快时效
A23: 【敏感度结论】
A25: 敏感因素 | B25: 影响程度 | C25: 控制建议
A26: 头程运输 | B26: 高 | C26: 选择稳定物流商，签订SLA
A27: 清关效率 | B27: 中 | C27: 选择包税渠道，提前准备资料
A28: 尾程派送 | B28: 中 | C28: 多备用渠道，监控妥投率
A29: 季节性波动 | B29: 高 | C29: 旺季前2个月开始备货

Sheet 使用说明
A1: 【物流时效策略模型使用说明】
A3: 一、模型核心逻辑
A5: 本模型基于头程时效 + 尾程时效，计算全链路物流时效，
A6: 支持时效优先、平衡策略、成本优先三种策略对比，
A7: 帮助选择最合适的物流渠道组合。
A9: 二、时效计算公式
A11: 头程时效 = 从发货到海外仓入库的天数
A12: 尾程时效 = 从海外仓出库到客户签收的天数
A13: 全链路时效 = 头程时效 + 尾程时效
A15: 三、三种时效策略
A17: 1. 时效优先策略
A18: - 渠道：空运 + 快速尾程
... A101: 📅 每年：重新评估策略
